WARNING:sphinx.sphinx.util.display:yyyyyy
WARNING:sphinx.sphinx.util.nodes:yyyyyy
WARNING:sphinx.sphinx.util:yyyyyy
WARNING:sphinx.sphinx.config:yyyyyy
WARNING:sphinx.sphinx.environment.adapters.toctree:yyyyyy
WARNING:sphinx.sphinx.util.docutils:yyyyyy
WARNING:sphinx.sphinx.util.i18n:yyyyyy
WARNING:sphinx.sphinx.transforms:yyyyyy
WARNING:sphinx.sphinx.environment:yyyyyy
WARNING:sphinx.sphinx.util.inspect:yyyyyy
WARNING:sphinx.sphinx.events:yyyyyy
WARNING:sphinx.sphinx.highlighting:yyyyyy
WARNING:sphinx.sphinx.project:yyyyyy
WARNING:sphinx.sphinx.util.docfields:yyyyyy
WARNING:sphinx.sphinx.domains.std:yyyyyy
WARNING:sphinx.sphinx.extension:yyyyyy
WARNING:sphinx.sphinx.transforms.i18n:yyyyyy
WARNING:sphinx.sphinx.io:yyyyyy
WARNING:sphinx.sphinx.util.rst:yyyyyy
WARNING:sphinx.sphinx.registry:yyyyyy
WARNING:sphinx.sphinx.application:yyyyyy
WARNING:sphinx.sphinx.cmd.build:ffffffin
ERROR:asyncio:Exception in callback _ProactorBasePipeTransport._call_connection_lost(None)
handle: <Handle _ProactorBasePipeTransport._call_connection_lost(None)>
Traceback (most recent call last):
  File "C:\Users\zxouyang\AppData\Local\anaconda3\envs\resume\Lib\asyncio\events.py", line 88, in _run
    self._context.run(self._callback, *self._args)
  File "C:\Users\zxouyang\AppData\Local\anaconda3\envs\resume\Lib\asyncio\proactor_events.py", line 165, in _call_connection_lost
    self._sock.shutdown(socket.SHUT_RDWR)
ConnectionResetError: [WinError 10054] An existing connection was forcibly closed by the remote host
